2020/11/23 07:00:39 Attempt 1 of http call to http://10.0.0.8:16384/sendlogstoartifacts/info
2020/11/23 07:00:39 Attempt 1 of http call to http://10.0.0.8:16384/sendlogstoartifacts/status
[2020-11-23T07:00:40.185295] Entering context manager injector.
[context_manager_injector.py] Command line Options: Namespace(inject=['ProjectPythonPath:context_managers.ProjectPythonPath', 'RunHistory:context_managers.RunHistory', 'TrackUserError:context_managers.TrackUserError'], invocation=['train.py', '--C', '2.5998421683728825', '--max_iter', '84'])
Script type = None
Starting the daemon thread to refresh tokens in background for process with pid = 104
Entering Run History Context Manager.
Current directory:  /mnt/batch/tasks/shared/LS_root/jobs/quick-starts-ws-127474/azureml/hd_2faa6195-a191-467b-be06-78b4e7f50370_87/mounts/workspaceblobstore/azureml/HD_2faa6195-a191-467b-be06-78b4e7f50370_87
Preparing to call script [ train.py ] with arguments: ['--C', '2.5998421683728825', '--max_iter', '84']
After variable expansion, calling script [ train.py ] with arguments: ['--C', '2.5998421683728825', '--max_iter', '84']

Getting existing workspace
Starting the daemon thread to refresh tokens in background for process with pid = 104


[2020-11-23T07:00:43.701053] The experiment failed. Finalizing run...
Cleaning up all outstanding Run operations, waiting 900.0 seconds
1 items cleaning up...
Cleanup took 0.0667123794555664 seconds
Traceback (most recent call last):
  File "/mnt/batch/tasks/shared/LS_root/jobs/quick-starts-ws-127474/azureml/hd_2faa6195-a191-467b-be06-78b4e7f50370_87/mounts/workspaceblobstore/azureml/HD_2faa6195-a191-467b-be06-78b4e7f50370_87/azureml-setup/context_manager_injector.py", line 192, in execute_with_context
    runpy.run_path(sys.argv[0], globals(), run_name="__main__")
  File "/opt/miniconda/lib/python3.6/runpy.py", line 263, in run_path
    pkg_name=pkg_name, script_name=fname)
  File "/opt/miniconda/lib/python3.6/runpy.py", line 96, in _run_module_code
    mod_name, mod_spec, pkg_name, script_name)
  File "/opt/miniconda/lib/python3.6/runpy.py", line 85, in _run_code
    exec(code, run_globals)
  File "train.py", line 54, in <module>
    ws = Workspace.from_config()
  File "/opt/miniconda/lib/python3.6/site-packages/azureml/core/workspace.py", line 260, in from_config
    'config.json exists in the parent directories.'.format(normalized_path))
azureml.exceptions._azureml_exception.UserErrorException: UserErrorException:
	Message: We could not find config.json in: /mnt/batch/tasks/shared/LS_root/jobs/quick-starts-ws-127474/azureml/hd_2faa6195-a191-467b-be06-78b4e7f50370_87/mounts/workspaceblobstore/azureml/HD_2faa6195-a191-467b-be06-78b4e7f50370_87 or in its parent directories. Please provide the full path to the config file or ensure that config.json exists in the parent directories.
	InnerException None
	ErrorResponse 
{
    "error": {
        "code": "UserError",
        "message": "We could not find config.json in: /mnt/batch/tasks/shared/LS_root/jobs/quick-starts-ws-127474/azureml/hd_2faa6195-a191-467b-be06-78b4e7f50370_87/mounts/workspaceblobstore/azureml/HD_2faa6195-a191-467b-be06-78b4e7f50370_87 or in its parent directories. Please provide the full path to the config file or ensure that config.json exists in the parent directories."
    }
}

During handling of the above exception, another exception occurred:

Traceback (most recent call last):
  File "train.py", line 54, in <module>
    ws = Workspace.from_config()
  File "/opt/miniconda/lib/python3.6/site-packages/azureml/core/workspace.py", line 260, in from_config
    'config.json exists in the parent directories.'.format(normalized_path))
UserScriptException: UserScriptException:
	Message: We could not find config.json in: /mnt/batch/tasks/shared/LS_root/jobs/quick-starts-ws-127474/azureml/hd_2faa6195-a191-467b-be06-78b4e7f50370_87/mounts/workspaceblobstore/azureml/HD_2faa6195-a191-467b-be06-78b4e7f50370_87 or in its parent directories. Please provide the full path to the config file or ensure that config.json exists in the parent directories.
	InnerException UserErrorException:
	Message: We could not find config.json in: /mnt/batch/tasks/shared/LS_root/jobs/quick-starts-ws-127474/azureml/hd_2faa6195-a191-467b-be06-78b4e7f50370_87/mounts/workspaceblobstore/azureml/HD_2faa6195-a191-467b-be06-78b4e7f50370_87 or in its parent directories. Please provide the full path to the config file or ensure that config.json exists in the parent directories.
	InnerException None
	ErrorResponse 
{
    "error": {
        "code": "UserError",
        "message": "We could not find config.json in: /mnt/batch/tasks/shared/LS_root/jobs/quick-starts-ws-127474/azureml/hd_2faa6195-a191-467b-be06-78b4e7f50370_87/mounts/workspaceblobstore/azureml/HD_2faa6195-a191-467b-be06-78b4e7f50370_87 or in its parent directories. Please provide the full path to the config file or ensure that config.json exists in the parent directories."
    }
}
	ErrorResponse 
{
    "error": {
        "code": "UserError",
        "message": "We could not find config.json in: /mnt/batch/tasks/shared/LS_root/jobs/quick-starts-ws-127474/azureml/hd_2faa6195-a191-467b-be06-78b4e7f50370_87/mounts/workspaceblobstore/azureml/HD_2faa6195-a191-467b-be06-78b4e7f50370_87 or in its parent directories. Please provide the full path to the config file or ensure that config.json exists in the parent directories."
    }
}

[2020-11-23T07:00:44.601430] Finished context manager injector with Exception.
2020/11/23 07:00:45 Failed to run the wrapper cmd with err: exit status 1
2020/11/23 07:00:45 Attempt 1 of http call to http://10.0.0.8:16384/sendlogstoartifacts/status
2020/11/23 07:00:45 mpirun version string: {
Intel(R) MPI Library for Linux* OS, Version 2018 Update 3 Build 20180411 (id: 18329)
Copyright 2003-2018 Intel Corporation.
}
2020/11/23 07:00:45 MPI publisher: intel ; version: 2018
2020/11/23 07:00:45 Process Exiting with Code:  1
